<robot name="wsg_32_description">
  <link name="world">
    <inertial> <origin rpy="0 0 0" xyz="0 0 0" /> <mass value="1E-10" /> <inertia ixx="0" ixy="0" ixz="0" iyy="0" iyz="0" izz="0" /></inertial>
  </link>

  <link name="prismatic_x">
    <inertial> <origin rpy="0 0 0" xyz="0 0 0" /> <mass value="1E-10" /> <inertia ixx="0" ixy="0" ixz="0" iyy="0" iyz="0" izz="0" /></inertial>
  </link>
  <link name="prismatic_y">
    <inertial> <origin rpy="0 0 0" xyz="0 0 0" /> <mass value="1E-10" /> <inertia ixx="0" ixy="0" ixz="0" iyy="0" iyz="0" izz="0" /></inertial>
  </link>
  <link name="prismatic_z">
    <inertial> <origin rpy="0 0 0" xyz="0 0 0" /> <mass value="1E-10" /> <inertia ixx="0" ixy="0" ixz="0" iyy="0" iyz="0" izz="0" /></inertial>
  </link>
  <link name="revolute_z">
    <inertial> <origin rpy="0 0 0" xyz="0 0 0" /> <mass value="1E-10" /> <inertia ixx="0" ixy="0" ixz="0" iyy="0" iyz="0" izz="0" /></inertial>
  </link>

  <joint name="x_to_world" type="prismatic">
    <parent link="world" />
    <child link="prismatic_x" />
    <axis xyz="1 0 0" />
    <limit lower="-10" upper="10" velocity="10.0" />
    <origin rpy="0 0 0" xyz="0 0 0" />
  </joint>

  <joint name="y_to_x" type="prismatic">
    <parent link="prismatic_x" />
    <child link="prismatic_y" />
    <axis xyz="0 1 0" />
    <limit lower="-10" upper="10" velocity="10.0" />
    <origin rpy="0 0 0" xyz="0 0 0" />
  </joint>
  <joint name="z_to_y" type="prismatic">
    <parent link="prismatic_y" />
    <child link="prismatic_z" />
    <axis xyz="0 0 1" />
    <limit lower="-10" upper="10" velocity="10.0" />
    <origin rpy="0 0 0" xyz="0 0 0" />
  </joint>
  <joint name="rev_z_to_prism_z" type="continuous">
    <parent link="prismatic_z" />
    <child link="revolute_z" />
    <axis xyz="0 0 1" />
    <limit effort="100000" lower="-3.14" upper="3.14" velocity="1" />
    <origin rpy="0 0 0" xyz="0 0 0" />
  </joint>
  
  <joint name="hand_to_z" type="fixed">
    <parent link="revolute_z" />
    <child link="hand_link" />
    <origin rpy="3.1415926535 0 0" xyz="0 0 0" />
  </joint>


  <link name="hand_link">
    <inertial>
      <origin rpy="0 0 0" xyz="0 0 0" />
      <mass value="0.19187770361295" />
      <inertia ixx="0.000259095961095666" ixy="-4.42589635811335E-08" ixz="-8.19503266406055E-09" iyy="6.70924748330843E-05" iyz="-6.65748470338111E-06" izz="0.000219527960705521" />
    </inertial>

    <visual>
      <origin rpy="0 0 0" xyz="0 0 0" />
      <geometry>
        <mesh filename="./arm_meshes/hand_link.stl" />
      </geometry>
      <material name="">
        <color rgba="0.792156862745098 0.819607843137255 0.933333333333333 1" />
      </material>
    </visual>
    <collision>
      <origin rpy="0 0 0" xyz="0 0 0" />
      <geometry>
        <mesh filename="./arm_meshes/hand_link.stl" />
      </geometry>
    </collision>
  </link>

  


  <link name="wsg_32_gripper_base_link_gripper_right">
    <inertial>
      <origin rpy="0 0 0" xyz="-2.850603053553E-05 -0.00191114285188175 0.00382933445364996" />
      <mass value="0.5" />
      <inertia ixx="3.06504383705634E-10" ixy="5.74222476890191E-11" ixz="-2.40533503848462E-10" iyy="4.90275789305826E-10" iyz="6.8945176052368E-11" izz="2.18298925049827E-10" />
    </inertial>
    <visual>
      <origin rpy="0 1.57079 0" xyz="-0.00725 0 0.0004" />
      <geometry>
        <mesh filename="./arm_meshes/right_link.stl" />
      </geometry>
      <material name="">
        <color rgba="0.792156862745098 0.819607843137255 0.933333333333333 1" />
      </material>
    </visual>
    <collision>
      <origin rpy="0 1.57079 0" xyz="-0.00725 0 0.0004" />
      <geometry>
        <mesh filename="./arm_meshes/right_link.stl" />
      </geometry>
    </collision>
  </link>
  <joint name="wsg_32_gripper_base_joint_gripper_right" type="prismatic">
    <origin rpy="3.1416 -1.5708 0" xyz="-0.0003903 -0.009 0.069014" />
    <parent link="hand_link" />
    <child link="wsg_32_gripper_base_link_gripper_right" />
    <axis xyz="0 -1 0" />
    <limit effort="100" lower="-0.028" upper="0" velocity="0" />
  </joint>





  <link name="wsg_32_gripper_base_link_gripper_left">
    <inertial>
      <origin rpy="-1.57079 3.14159 -1.57079" xyz="-2.72000777333109E-05 -0.00460993992652343 -0.00191114282807962" />
      <mass value="0.5" />
      <inertia ixx="3.06504383705634E-10" ixy="2.40533503848236E-10" ixz="5.74222476899625E-11" iyy="2.18298925050368E-10" iyz="-6.89451760534347E-11" izz="4.90275789305286E-10" />
    </inertial>
    <visual>
      <origin rpy="-1.57079 3.14159  -1.57079" xyz="-0.00725 0 0.0004" />
      <geometry>
        <mesh filename="./arm_meshes/left_link.stl" />
      </geometry>
      <material name="">
        <color rgba="0.792156862745098 0.819607843137255 0.933333333333333 1" />
      </material>
    </visual>
    <collision>
      <origin rpy="-1.57079 3.14159  -1.57079" xyz="-0.00725 0 0.0004" />
      <geometry>
        <mesh filename="./arm_meshes/left_link.stl" />
      </geometry>
    </collision>
  </link>
  <joint name="wsg_32_gripper_base_joint_gripper_left" type="prismatic">
    <origin rpy="-1.5708 -1.5708 0" xyz="-0.0003903 0.009 0.069014" />
    <parent link="hand_link" />
    <child link="wsg_32_gripper_base_link_gripper_left" />
    <axis xyz="0 0 1" />
    <limit effort="100" lower="0" upper="0.028" velocity="0" />
  </joint>


  

  <link name="left_finger_link">
    <inertial>
      <origin rpy="0 0 0" xyz="0 0 0" />
      <mass value="0.01" />
      <inertia ixx="3.06504383705634E-10" ixy="2.40533503848236E-10" ixz="5.74222476899625E-11" iyy="2.18298925050368E-10" iyz="-6.89451760534347E-11" izz="4.90275789305286E-10" />
    </inertial>
    <visual>
      <origin rpy="0 0 0" xyz="-0.01 0 0.00" />
      <geometry>
        <mesh filename="./arm_meshes/left_finger.stl" />
      </geometry>
      <material name="det">
        <color rgba="0.75 0.75 0.75 1" />
      </material>
    </visual>
    <collision>
      <origin rpy="0 0 0" xyz="-0.01 0 0.00" />
      <geometry>
        <mesh filename="./arm_meshes/left_finger.stl" />
      </geometry>
    </collision>
  </link>
  <joint name="left_finger_joint" type="fixed">
    <origin rpy="0 -1.57079 -1.57079" xyz="0.00755 0.0 0.0055" />
    <parent link="wsg_32_gripper_base_link_gripper_left" />
    <child link="left_finger_link" />
  </joint>


  <link name="right_finger_link">
    <inertial>
      <origin rpy="0 0 0" xyz="0 0 0" />
      <mass value="0.01" />
      <inertia ixx="3.06504383705634E-10" ixy="2.40533503848236E-10" ixz="5.74222476899625E-11" iyy="2.18298925050368E-10" iyz="-6.89451760534347E-11" izz="4.90275789305286E-10" />
    </inertial>
    <visual>
      <origin rpy="0 0 0" xyz="-0.00 0 0.00" />
      <geometry>
        <mesh filename="./arm_meshes/right_finger.stl" />
      </geometry>
      <material name="det2">
        <color rgba="0.9 0.1 0.2 1" />
      </material>
    </visual>
    <collision>
      <origin rpy="0 0 0" xyz="-0.00 0 0.00" />
      <geometry>
        <mesh filename="./arm_meshes/right_finger.stl" />
      </geometry>
    </collision>
  </link>
  <joint name="right_finger_joint" type="fixed">
    <origin rpy="0 3.14159 -1.57079" xyz="0.00755 -0.0045 0" />
    <parent link="wsg_32_gripper_base_link_gripper_right" />
    <child link="right_finger_link" />
  </joint>


</robot>